<?xml version="0.0" ?>
<robot name="abb_irb140">
	<link name="base_link">
		<inertial>
			<origin rpy="0.00000 -0.00000 0.00000" xyz="0.00000 0.00000 0.00000"/>
			<mass value="0.00000"/>
			<inertia ixx="0.00000" ixy="0" ixz="0" iyy="0.00000" iyz="0" izz="0.00000"/>
		</inertial>
		<visual>
			<origin rpy="0.00000 -0.00000 0.00000" xyz="0.00000 0.00000 0.00000"/>
			<geometry>
				<mesh filename="./meshes/irb140/visual/base_link.stl" scale="0.01000 0.01000 0.01000"/>
			</geometry>
			<material name="mat_-1_0">
				<color rgba="1.00000 0.43000 0.00000 1.00000" />
			</material>
		</visual>
		<collision>
			<origin rpy="0.00000 -0.00000 0.00000" xyz="0.00000 0.00000 0.00000"/>
			<geometry>
				<mesh filename="./meshes/irb140/collision/base_link.stl" scale="0.01000 0.01000 0.01000"/>
			</geometry>
		</collision>
	</link>
	<link name="link_1">
		<inertial>
			<origin rpy="0.00000 -0.00000 0.00000" xyz="0.00000 0.00000 0.00000"/>
			<mass value="1.00000"/>
			<inertia ixx="0.02114" ixy="0" ixz="0" iyy="0.02172" iyz="0" izz="0.02016"/>
		</inertial>
		<visual>
			<origin rpy="0.00000 -0.00000 0.00000" xyz="0.00000 0.00000 0.00000"/>
			<geometry>
				<mesh filename="./meshes/irb140/visual/link_1.stl" scale="0.01000 0.01000 0.01000"/>
			</geometry>
			<material name="mat_0_0">
				<color rgba="1.00000 0.43000 0.00000 1.00000" />
			</material>
		</visual>
		<collision>
			<origin rpy="0.00000 -0.00000 0.00000" xyz="0.00000 0.00000 0.00000"/>
			<geometry>
				<mesh filename="./meshes/irb140/collision/link_1.stl" scale="0.01000 0.01000 0.01000"/>
			</geometry>
		</collision>
	</link>
	<link name="link_2">
		<inertial>
			<origin rpy="0.00000 -0.00000 0.00000" xyz="0.00000 0.00000 0.00000"/>
			<mass value="1.00000"/>
			<inertia ixx="0.02914" ixy="0" ixz="0" iyy="0.02557" iyz="0" izz="0.00946"/>
		</inertial>
		<visual>
			<origin rpy="0.00000 -0.00000 0.00000" xyz="-0.07000 0.00000 -0.35200"/>
			<geometry>
				<mesh filename="./meshes/irb140/visual/link_2.stl" scale="0.01000 0.01000 0.01000"/>
			</geometry>
			<material name="mat_1_0">
				<color rgba="1.00000 0.43000 0.00000 1.00000" />
			</material>
		</visual>
		<collision>
			<origin rpy="0.00000 -0.00000 0.00000" xyz="-0.07000 0.00000 -0.35200"/>
			<geometry>
				<mesh filename="./meshes/irb140/collision/link_2.stl" scale="0.01000 0.01000 0.01000"/>
			</geometry>
		</collision>
	</link>
	<link name="link_3">
		<inertial>
			<origin rpy="0.00000 -0.00000 0.00000" xyz="0.00000 0.00000 0.00000"/>
			<mass value="1.00000"/>
			<inertia ixx="0.00606" ixy="0" ixz="0" iyy="0.01645" iyz="0" izz="0.01544"/>
		</inertial>
		<visual>
			<origin rpy="0.00000 -0.00000 0.00000" xyz="-0.07000 0.06500 -0.71200"/>
			<geometry>
				<mesh filename="./meshes/irb140/visual/link_3.stl" scale="0.01000 0.01000 0.01000"/>
			</geometry>
			<material name="mat_2_0">
				<color rgba="1.00000 0.43000 0.00000 1.00000" />
			</material>
		</visual>
		<collision>
			<origin rpy="0.00000 -0.00000 0.00000" xyz="-0.07000 0.06500 -0.71200"/>
			<geometry>
				<mesh filename="./meshes/irb140/collision/link_3.stl" scale="0.01000 0.01000 0.01000"/>
			</geometry>
		</collision>
	</link>
	<link name="link_4">
		<inertial>
			<origin rpy="0.00000 -0.00000 0.00000" xyz="0.00000 0.00000 0.00000"/>
			<mass value="1.00000"/>
			<inertia ixx="0.00280" ixy="0" ixz="0" iyy="0.00532" iyz="0" izz="0.00581"/>
		</inertial>
		<visual>
			<origin rpy="0.00000 -0.00000 0.00000" xyz="-0.30900 0.00000 -0.71200"/>
			<geometry>
				<mesh filename="./meshes/irb140/visual/link_4.stl" scale="0.01000 0.01000 0.01000"/>
			</geometry>
			<material name="mat_3_0">
				<color rgba="1.00000 0.43000 0.00000 1.00000" />
			</material>
		</visual>
		<collision>
			<origin rpy="0.00000 -0.00000 0.00000" xyz="-0.30900 0.00000 -0.71200"/>
			<geometry>
				<mesh filename="./meshes/irb140/collision/link_4.stl" scale="0.01000 0.01000 0.01000"/>
			</geometry>
		</collision>
	</link>
	<link name="link_5">
		<inertial>
			<origin rpy="0.00000 -0.00000 0.00000" xyz="0.00000 0.00000 0.00000"/>
			<mass value="1.00000"/>
			<inertia ixx="0.00080" ixy="0" ixz="0" iyy="0.00137" iyz="0" izz="0.00080"/>
		</inertial>
		<visual>
			<origin rpy="0.00000 -0.00000 0.00000" xyz="-0.45000 0.00000 -0.71200"/>
			<geometry>
				<mesh filename="./meshes/irb140/visual/link_5.stl" scale="0.01000 0.01000 0.01000"/>
			</geometry>
			<material name="mat_4_0">
				<color rgba="1.00000 0.43000 0.00000 1.00000" />
			</material>
		</visual>
		<collision>
			<origin rpy="0.00000 -0.00000 0.00000" xyz="-0.45000 0.00000 -0.71200"/>
			<geometry>
				<mesh filename="./meshes/irb140/collision/link_5.stl" scale="0.01000 0.01000 0.01000"/>
			</geometry>
		</collision>
	</link>
	<link name="link_6">
		<inertial>
			<origin rpy="0.00000 -0.00000 0.00000" xyz="0.00000 0.00000 0.00000"/>
			<mass value="1.00000"/>
			<inertia ixx="0.00052" ixy="0" ixz="0" iyy="0.00046" iyz="0" izz="0.00046"/>
		</inertial>
		<visual>
			<origin rpy="0.00000 -0.00000 0.00000" xyz="-0.51500 0.00000 -0.71200"/>
			<geometry>
				<mesh filename="./meshes/irb140/visual/link_6.stl" scale="0.01000 0.01000 0.01000"/>
			</geometry>
			<material name="mat_5_0">
				<color rgba="1.00000 0.43000 0.00000 1.00000" />
			</material>
		</visual>
		<collision>
			<origin rpy="0.00000 -0.00000 0.00000" xyz="-0.51500 0.00000 -0.71200"/>
			<geometry>
				<mesh filename="./meshes/irb140/collision/link_6.stl" scale="0.01000 0.01000 0.01000"/>
			</geometry>
		</collision>
	</link>
	<link name="tool0">
		<inertial>
			<origin rpy="0.00000 -0.00000 0.00000" xyz="0.00000 0.00000 0.00000"/>
			<mass value="1.00000"/>
			<inertia ixx="0.00000" ixy="0" ixz="0" iyy="0.00000" iyz="0" izz="0.00000"/>
		</inertial>
	</link>
	<link name="base">
		<inertial>
			<origin rpy="0.00000 -0.00000 0.00000" xyz="0.00000 0.00000 0.00000"/>
			<mass value="1.00000"/>
			<inertia ixx="0.00000" ixy="0" ixz="0" iyy="0.00000" iyz="0" izz="0.00000"/>
		</inertial>
	</link>
	<link name="robotiq_arg2f_base_link">
		<inertial>
			<origin rpy="0.00000 -0.00000 0.00000" xyz="0.00000 -0.00000 0.03145"/>
			<mass value="0.00000"/>
			<inertia ixx="0.00000" ixy="0" ixz="0" iyy="0.00000" iyz="0" izz="0.00000"/>
		</inertial>
		<visual>
			<origin rpy="0.00000 -0.00000 0.00000" xyz="0.00000 0.00000 0.00000"/>
			<geometry>
				<mesh filename="urdfs/robotiq_140_gripper_description/urdf/../meshes/robotiq_140/visual/robotiq_arg2f_base_link.stl" scale="1.00000 1.00000 1.00000"/>
			</geometry>
			<material name="mat_-1_0">
				<color rgba="0.10000 0.10000 0.10000 1.00000" />
			</material>
		</visual>
		<collision>
			<origin rpy="0.00000 -0.00000 0.00000" xyz="0.00000 0.00000 0.00000"/>
			<geometry>
				<mesh filename="urdfs/robotiq_140_gripper_description/urdf/../meshes/robotiq_140/collision/robotiq_arg2f_base_link.stl" scale="1.00000 1.00000 1.00000"/>
			</geometry>
		</collision>
	</link>
	<link name="left_outer_knuckle">
		<inertial>
			<origin rpy="0.00000 -0.00000 0.00000" xyz="-0.00020 0.01994 0.02922"/>
			<mass value="0.00853"/>
			<inertia ixx="0.00000" ixy="0" ixz="0" iyy="0.00000" iyz="0" izz="0.00000"/>
		</inertial>
		<visual>
			<origin rpy="0.00000 -0.00000 0.00000" xyz="0.00000 0.00000 0.00000"/>
			<geometry>
				<mesh filename="urdfs/robotiq_140_gripper_description/urdf/../meshes/robotiq_140/visual/robotiq_arg2f_140_outer_knuckle.stl" scale="1.00000 1.00000 1.00000"/>
			</geometry>
			<material name="mat_0_0">
				<color rgba="0.10000 0.10000 0.10000 1.00000" />
			</material>
		</visual>
		<collision>
			<origin rpy="0.00000 -0.00000 0.00000" xyz="0.00000 0.00000 0.00000"/>
			<geometry>
				<mesh filename="urdfs/robotiq_140_gripper_description/urdf/../meshes/robotiq_140/collision/robotiq_arg2f_140_outer_knuckle.stl" scale="1.00000 1.00000 1.00000"/>
			</geometry>
		</collision>
	</link>
	<link name="left_outer_finger">
		<inertial>
			<origin rpy="0.00000 -0.00000 0.00000" xyz="0.00030 0.03739 -0.02080"/>
			<mass value="0.02261"/>
			<inertia ixx="0.00002" ixy="0" ixz="0" iyy="0.00001" iyz="0" izz="0.00002"/>
		</inertial>
		<visual>
			<origin rpy="0.00000 -0.00000 0.00000" xyz="0.00000 0.00000 0.00000"/>
			<geometry>
				<mesh filename="urdfs/robotiq_140_gripper_description/urdf/../meshes/robotiq_140/visual/robotiq_arg2f_140_outer_finger.stl" scale="1.00000 1.00000 1.00000"/>
			</geometry>
			<material name="mat_1_0">
				<color rgba="0.10000 0.10000 0.10000 1.00000" />
			</material>
		</visual>
		<collision>
			<origin rpy="0.00000 -0.00000 0.00000" xyz="0.00000 0.00000 0.00000"/>
			<geometry>
				<mesh filename="urdfs/robotiq_140_gripper_description/urdf/../meshes/robotiq_140/collision/robotiq_arg2f_140_outer_finger.stl" scale="1.00000 1.00000 1.00000"/>
			</geometry>
		</collision>
	</link>
	<link name="left_inner_finger">
		<inertial>
			<origin rpy="0.00000 -0.00000 0.00000" xyz="0.00030 0.01601 -0.01369"/>
			<mass value="0.01040"/>
			<inertia ixx="0.00000" ixy="0" ixz="0" iyy="0.00000" iyz="0" izz="0.00000"/>
		</inertial>
		<visual>
			<origin rpy="0.00000 -0.00000 0.00000" xyz="0.00000 0.00000 0.00000"/>
			<geometry>
				<mesh filename="urdfs/robotiq_140_gripper_description/urdf/../meshes/robotiq_140/visual/robotiq_arg2f_140_inner_finger.stl" scale="1.00000 1.00000 1.00000"/>
			</geometry>
			<material name="mat_2_0">
				<color rgba="0.10000 0.10000 0.10000 1.00000" />
			</material>
		</visual>
		<collision>
			<origin rpy="0.00000 -0.00000 0.00000" xyz="0.00000 0.00000 0.00000"/>
			<geometry>
				<mesh filename="urdfs/robotiq_140_gripper_description/urdf/../meshes/robotiq_140/collision/robotiq_arg2f_140_inner_finger.stl" scale="1.00000 1.00000 1.00000"/>
			</geometry>
		</collision>
	</link>
	<link name="left_inner_finger_pad">
		<contact>
			<lateral_friction value="1.0"/>
			<rolling_friction value="0.0"/>
			<contact_cfm value="0.0"/>
			<contact_erp value="1.0"/>
		</contact>
		<inertial>
			<origin rpy="0.00000 -0.00000 0.00000" xyz="0.00000 0.00000 0.00000"/>
			<mass value="1.00000"/>
			<inertia ixx="0.00041" ixy="0" ixz="0" iyy="0.00008" iyz="0" izz="0.00048"/>
		</inertial>
		<visual>
			<origin rpy="0.00000 -0.00000 0.00000" xyz="0.00000 0.00000 0.00000"/>
			<geometry>
				<box size="0.02700 0.06500 0.00750"/>
			</geometry>
			<material name="mat_3_0">
				<color rgba="0.10000 0.10000 0.10000 1.00000" />
			</material>
		</visual>
		<collision>
			<origin rpy="0.00000 -0.00000 0.00000" xyz="0.00000 0.00000 0.00000"/>
			<geometry>
				<box size="0.03000 0.07000 0.00750"/>
			</geometry>
		</collision>
	</link>
	<link name="left_inner_knuckle">
		<inertial>
			<origin rpy="0.00000 -0.00000 0.00000" xyz="0.00012 0.05079 0.00104"/>
			<mass value="0.02712"/>
			<inertia ixx="0.00003" ixy="0" ixz="0" iyy="0.00001" iyz="0" izz="0.00004"/>
		</inertial>
		<visual>
			<origin rpy="0.00000 -0.00000 0.00000" xyz="0.00000 0.00000 0.00000"/>
			<geometry>
				<mesh filename="urdfs/robotiq_140_gripper_description/urdf/../meshes/robotiq_140/visual/robotiq_arg2f_140_inner_knuckle.stl" scale="1.00000 1.00000 1.00000"/>
			</geometry>
			<material name="mat_4_0">
				<color rgba="0.10000 0.10000 0.10000 1.00000" />
			</material>
		</visual>
		<collision>
			<origin rpy="0.00000 -0.00000 0.00000" xyz="0.00000 0.00000 0.00000"/>
			<geometry>
				<mesh filename="urdfs/robotiq_140_gripper_description/urdf/../meshes/robotiq_140/collision/robotiq_arg2f_140_inner_knuckle.stl" scale="1.00000 1.00000 1.00000"/>
			</geometry>
		</collision>
	</link>
	<link name="right_outer_knuckle">
		<inertial>
			<origin rpy="0.00000 -0.00000 0.00000" xyz="-0.00020 0.01994 0.02922"/>
			<mass value="0.00853"/>
			<inertia ixx="0.00000" ixy="0" ixz="0" iyy="0.00000" iyz="0" izz="0.00000"/>
		</inertial>
		<visual>
			<origin rpy="0.00000 -0.00000 0.00000" xyz="0.00000 0.00000 0.00000"/>
			<geometry>
				<mesh filename="urdfs/robotiq_140_gripper_description/urdf/../meshes/robotiq_140/visual/robotiq_arg2f_140_outer_knuckle.stl" scale="1.00000 1.00000 1.00000"/>
			</geometry>
			<material name="mat_5_0">
				<color rgba="0.10000 0.10000 0.10000 1.00000" />
			</material>
		</visual>
		<collision>
			<origin rpy="0.00000 -0.00000 0.00000" xyz="0.00000 0.00000 0.00000"/>
			<geometry>
				<mesh filename="urdfs/robotiq_140_gripper_description/urdf/../meshes/robotiq_140/collision/robotiq_arg2f_140_outer_knuckle.stl" scale="1.00000 1.00000 1.00000"/>
			</geometry>
		</collision>
	</link>
	<link name="right_outer_finger">
		<inertial>
			<origin rpy="0.00000 -0.00000 0.00000" xyz="0.00030 0.03739 -0.02080"/>
			<mass value="0.02261"/>
			<inertia ixx="0.00002" ixy="0" ixz="0" iyy="0.00001" iyz="0" izz="0.00002"/>
		</inertial>
		<visual>
			<origin rpy="0.00000 -0.00000 0.00000" xyz="0.00000 0.00000 0.00000"/>
			<geometry>
				<mesh filename="urdfs/robotiq_140_gripper_description/urdf/../meshes/robotiq_140/visual/robotiq_arg2f_140_outer_finger.stl" scale="1.00000 1.00000 1.00000"/>
			</geometry>
			<material name="mat_6_0">
				<color rgba="0.10000 0.10000 0.10000 1.00000" />
			</material>
		</visual>
		<collision>
			<origin rpy="0.00000 -0.00000 0.00000" xyz="0.00000 0.00000 0.00000"/>
			<geometry>
				<mesh filename="urdfs/robotiq_140_gripper_description/urdf/../meshes/robotiq_140/collision/robotiq_arg2f_140_outer_finger.stl" scale="1.00000 1.00000 1.00000"/>
			</geometry>
		</collision>
	</link>
	<link name="right_inner_finger">
		<inertial>
			<origin rpy="0.00000 -0.00000 0.00000" xyz="0.00030 0.01601 -0.01369"/>
			<mass value="0.01040"/>
			<inertia ixx="0.00000" ixy="0" ixz="0" iyy="0.00000" iyz="0" izz="0.00000"/>
		</inertial>
		<visual>
			<origin rpy="0.00000 -0.00000 0.00000" xyz="0.00000 0.00000 0.00000"/>
			<geometry>
				<mesh filename="urdfs/robotiq_140_gripper_description/urdf/../meshes/robotiq_140/visual/robotiq_arg2f_140_inner_finger.stl" scale="1.00000 1.00000 1.00000"/>
			</geometry>
			<material name="mat_7_0">
				<color rgba="0.10000 0.10000 0.10000 1.00000" />
			</material>
		</visual>
		<collision>
			<origin rpy="0.00000 -0.00000 0.00000" xyz="0.00000 0.00000 0.00000"/>
			<geometry>
				<mesh filename="urdfs/robotiq_140_gripper_description/urdf/../meshes/robotiq_140/collision/robotiq_arg2f_140_inner_finger.stl" scale="1.00000 1.00000 1.00000"/>
			</geometry>
		</collision>
	</link>
	<link name="right_inner_finger_pad">
		<contact>
			<lateral_friction value="1.0"/>
			<rolling_friction value="0.0"/>
			<contact_cfm value="0.0"/>
			<contact_erp value="1.0"/>
		</contact>

		<inertial>
			<origin rpy="0.00000 -0.00000 0.00000" xyz="0.00000 0.00000 0.00000"/>
			<mass value="1.00000"/>
			<inertia ixx="0.00041" ixy="0" ixz="0" iyy="0.00008" iyz="0" izz="0.00048"/>
		</inertial>
		<visual>
			<origin rpy="0.00000 -0.00000 0.00000" xyz="0.00000 0.00000 0.00000"/>
			<geometry>
				<box size="0.02700 0.06500 0.00750"/>
			</geometry>
			<material name="mat_8_0">
				<color rgba="0.10000 0.10000 0.10000 1.00000" />
			</material>
		</visual>
		<collision>
			<origin rpy="0.00000 -0.00000 0.00000" xyz="0.00000 0.00000 0.00000"/>
			<geometry>
				<box size="0.03000 0.07000 0.00750"/>
			</geometry>
		</collision>
	</link>
	<link name="right_inner_knuckle">
		<inertial>
			<origin rpy="0.00000 -0.00000 0.00000" xyz="0.00012 0.05079 0.00104"/>
			<mass value="0.02712"/>
			<inertia ixx="0.00003" ixy="0" ixz="0" iyy="0.00001" iyz="0" izz="0.00004"/>
		</inertial>
		<visual>
			<origin rpy="0.00000 -0.00000 0.00000" xyz="0.00000 0.00000 0.00000"/>
			<geometry>
				<mesh filename="urdfs/robotiq_140_gripper_description/urdf/../meshes/robotiq_140/visual/robotiq_arg2f_140_inner_knuckle.stl" scale="1.00000 1.00000 1.00000"/>
			</geometry>
			<material name="mat_9_0">
				<color rgba="0.10000 0.10000 0.10000 1.00000" />
			</material>
		</visual>
		<collision>
			<origin rpy="0.00000 -0.00000 0.00000" xyz="0.00000 0.00000 0.00000"/>
			<geometry>
				<mesh filename="urdfs/robotiq_140_gripper_description/urdf/../meshes/robotiq_140/collision/robotiq_arg2f_140_inner_knuckle.stl" scale="1.00000 1.00000 1.00000"/>
			</geometry>
		</collision>
	</link>
	<joint name="joint_1" type="revolute">
		<parent link="base_link"/>
		<child link="link_1"/>
		<limit effort="0.00000" lower="-3.14160" upper="3.14160" velocity="2.61800"/>
		<dynamics damping="1.0" friction="0.0001"/>
		<origin rpy="0.00000 -0.00000 0.00000" xyz="0.00000 0.00000 0.00000"/>
		<axis xyz="0.00000 0.00000 1.00000"/>
	</joint>
	<joint name="joint_2" type="revolute">
		<parent link="link_1"/>
		<child link="link_2"/>
		<limit effort="0.00000" lower="-1.74530" upper="1.74530" velocity="2.61800"/>
		<dynamics damping="1.0" friction="0.0001"/>
		<origin rpy="0.00000 -0.00000 0.00000" xyz="0.07000 0.00000 0.35200"/>
		<axis xyz="0.00000 1.00000 0.00000"/>
	</joint>
	<joint name="joint_3" type="revolute">
		<parent link="link_2"/>
		<child link="link_3"/>
		<limit effort="0.00000" lower="-2.44340" upper="2.44340" velocity="2.61800"/>
		<dynamics damping="1.0" friction="0.0001"/>
		<origin rpy="0.00000 -0.00000 0.00000" xyz="0.00000 -0.06500 0.36000"/>
		<axis xyz="0.00000 1.00000 0.00000"/>
	</joint>
	<joint name="joint_4" type="revolute">
		<parent link="link_3"/>
		<child link="link_4"/>
		<limit effort="0.00000" lower="-3.49000" upper="3.49000" velocity="6.28320"/>
		<dynamics damping="1.0" friction="0.0001"/>
		<origin rpy="0.00000 -0.00000 0.00000" xyz="0.23900 0.06500 0.00000"/>
		<axis xyz="1.00000 0.00000 0.00000"/>
	</joint>
	<joint name="joint_5" type="revolute">
		<parent link="link_4"/>
		<child link="link_5"/>
		<limit effort="0.00000" lower="-2.00710" upper="2.00710" velocity="6.28320"/>
		<dynamics damping="1.0" friction="0.0001"/>
		<origin rpy="0.00000 -0.00000 0.00000" xyz="0.14100 0.00000 0.00000"/>
		<axis xyz="0.00000 1.00000 0.00000"/>
	</joint>
	<joint name="joint_6" type="revolute">
		<parent link="link_5"/>
		<child link="link_6"/>
		<limit effort="0.00000" lower="-6.98130" upper="6.98130" velocity="7.85400"/>
		<dynamics damping="1.0" friction="0.0001"/>
		<origin rpy="0.00000 -0.00000 0.00000" xyz="0.06500 0.00000 0.00000"/>
		<axis xyz="1.00000 0.00000 0.00000"/>
	</joint>
	<joint name="joint_6-tool0" type="fixed">
		<parent link="link_6"/>
		<child link="tool0"/>
		<dynamics damping="1.0" friction="0.0001"/>
		<origin rpy="0.00000 -0.00000 0.00000" xyz="0.00000 0.00000 0.00000"/>
		<axis xyz="0.00000 0.00000 0.00000"/>
	</joint>
	<joint name="base_link-base" type="fixed">
		<parent link="base_link"/>
		<child link="base"/>
		<dynamics damping="1.0" friction="0.0001"/>
		<origin rpy="0.00000 -0.00000 0.00000" xyz="0.00000 0.00000 0.00000"/>
		<axis xyz="0.00000 0.00000 0.00000"/>
	</joint>
	<joint name="joint_dummy1" type="fixed">
		<parent link="link_6"/>
		<child link="robotiq_arg2f_base_link"/>
		<dynamics damping="1.0" friction="0.0001"/>
		<origin rpy="0.00000 1.57080 0.00000" xyz="0.00000 0.00000 0.00000"/>
		<axis xyz="0.00000 0.00000 1.00000"/>
	</joint>
	<joint name="finger_joint" type="revolute">
		<parent link="robotiq_arg2f_base_link"/>
		<child link="left_outer_knuckle"/>
		<limit effort="1000.00000" lower="0.00000" upper="0.72500" velocity="2.00000"/>
		<dynamics damping="1.0" friction="0.0001"/>
		<origin rpy="2.29580 -0.00000 0.00000" xyz="0.00000 -0.03060 0.05490"/>
		<axis xyz="-1.00000 0.00000 0.00000"/>
	</joint>
	<joint name="left_outer_finger_joint" type="fixed">
		<parent link="left_outer_knuckle"/>
		<child link="left_outer_finger"/>
		<dynamics damping="1.0" friction="0.0001"/>
		<origin rpy="0.00000 -0.00000 0.00000" xyz="0.00000 0.01822 0.02600"/>
		<axis xyz="0.00000 0.00000 0.00000"/>
	</joint>
	<joint name="left_inner_finger_joint" type="revolute">
		<parent link="left_outer_finger"/>
		<child link="left_inner_finger"/>
		<limit effort="1000.00000" lower="0.00000" upper="0.72500" velocity="2.00000"/>
		<dynamics damping="1.0" friction="0.0001"/>
		<origin rpy="-0.72500 0.00000 0.00000" xyz="0.00000 0.08176 -0.02822"/>
		<axis xyz="1.00000 0.00000 0.00000"/>
	</joint>
	<joint name="left_inner_finger_pad_joint" type="fixed">
		<parent link="left_inner_finger"/>
		<child link="left_inner_finger_pad"/>
		<dynamics damping="1.0" friction="0.0001"/>
		<origin rpy="0.00000 -0.00000 0.00000" xyz="0.00000 0.04576 -0.02722"/>
		<axis xyz="0.00000 0.00000 0.00000"/>
	</joint>
	<joint name="left_inner_knuckle_joint" type="revolute">
		<parent link="robotiq_arg2f_base_link"/>
		<child link="left_inner_knuckle"/>
		<limit effort="1000.00000" lower="-0.72500" upper="0.00000" velocity="2.00000"/>
		<dynamics damping="1.0" friction="0.0001"/>
		<origin rpy="2.29580 -0.00000 0.00000" xyz="0.00000 -0.01270 0.06142"/>
		<axis xyz="1.00000 0.00000 0.00000"/>
	</joint>
	<joint name="right_outer_knuckle_joint" type="revolute">
		<parent link="robotiq_arg2f_base_link"/>
		<child link="right_outer_knuckle"/>
		<limit effort="1000.00000" lower="-0.72500" upper="0.00000" velocity="2.00000"/>
		<dynamics damping="1.0" friction="0.0001"/>
		<origin rpy="2.29580 0.00000 3.14159" xyz="0.00000 0.03060 0.05490"/>
		<axis xyz="1.00000 0.00000 0.00000"/>
	</joint>
	<joint name="right_outer_finger_joint" type="fixed">
		<parent link="right_outer_knuckle"/>
		<child link="right_outer_finger"/>
		<dynamics damping="1.0" friction="0.0001"/>
		<origin rpy="0.00000 -0.00000 0.00000" xyz="0.00000 0.01822 0.02600"/>
		<axis xyz="0.00000 0.00000 0.00000"/>
	</joint>
	<joint name="right_inner_finger_joint" type="revolute">
		<parent link="right_outer_finger"/>
		<child link="right_inner_finger"/>
		<limit effort="1000.00000" lower="0.00000" upper="0.72500" velocity="2.00000"/>
		<dynamics damping="1.0" friction="0.0001"/>
		<origin rpy="-0.72500 0.00000 0.00000" xyz="0.00000 0.08176 -0.02822"/>
		<axis xyz="1.00000 0.00000 0.00000"/>
	</joint>
	<joint name="right_inner_finger_pad_joint" type="fixed">
		<parent link="right_inner_finger"/>
		<child link="right_inner_finger_pad"/>
		<dynamics damping="1.0" friction="0.0001"/>
		<origin rpy="0.00000 -0.00000 0.00000" xyz="0.00000 0.04576 -0.02722"/>
		<axis xyz="0.00000 0.00000 0.00000"/>
	</joint>
	<joint name="right_inner_knuckle_joint" type="revolute">
		<parent link="robotiq_arg2f_base_link"/>
		<child link="right_inner_knuckle"/>
		<limit effort="1000.00000" lower="-0.72500" upper="0.00000" velocity="2.00000"/>
		<dynamics damping="1.0" friction="0.0001"/>
		<origin rpy="2.29580 -0.00000 -3.14159" xyz="0.00000 0.01270 0.06142"/>
		<axis xyz="1.00000 0.00000 0.00000"/>
	</joint>
</robot>
